File: tgms/ExpDat_DQ2V(10K).txt
#EXPORTTYPE:DATA ALL
#FILE:DQ2V(10K).ngb-ds3
#FORMAT:NETZSCH5
#FTYPE:ANSI
#IDENTITY:1
#DECIMAL:POINT
#SEPARATOR:SEMICOLON
#MTYPE:DSC
#INSTRUMENT:NETZSCH STA 449F3
#PROJECT:调试
#DATE/TIME:23.08.2018 17:19
#CORR. FILE:基线Ar（1200,10K).ngb-bs3
#TEMPCAL:TCALZERO.TCX
#SENSITIVITY:SENSZERO.EXX
#LABORATORY:煤及煤系气重点实验室
#OPERATOR:wangchg
#REMARK:
#SAMPLE:DQ2V
#SAMPLE MASS /mg:10
#MATERIAL:煤样
#REFERENCE:空坩埚
#REFERENCE MASS /mg:0
#TYPE OF CRUCIBLE:DSC/TG pan Al2O3
#SAMPLE CRUCIBLE MASS /mg:0
#REFERENCE CRUCIBLE MASS /mg:0
#DSC RANGE /μV:5000
#TG RANGE /mg:35000
#TAU-R:---
#CORR. CODE:020
#EXO:-1
#RANGE:40°C/10.0(K/min)/1000°C
#SEGMENT:S1/1
#SEG. 1:40°C/10.0(K/min)/1000°C

##Temp./°C;Time/min;DSC/(uV/mg);Mass/%;Sensit./(uV/mW)
 37.46600; 0.00000;4.882814e-003;100.00000;1.00000
 37.47687; 0.14406;4.663322e-003; 99.98903;1.00000
 37.47672; 0.28811;4.692332e-003; 99.98794;1.00000
 37.49938; 0.43217;6.062070e-003; 99.98301;1.00000
 37.52237; 0.57623;6.502618e-003; 99.98595;1.00000
 37.59217; 0.72029;9.237908e-003; 99.98702;1.00000
 37.70664; 0.86434;1.199453e-002; 99.99952;1.00000
 37.84010; 1.00840;1.541404e-002;100.00331;1.00000
 38.05912; 1.15246;2.181466e-002;100.01724;1.00000
 38.30953; 1.29651;2.769259e-002;100.00452;1.00000
 38.63608; 1.44057;3.416336e-002;100.00529;1.00000
 39.03170; 1.58463;4.222060e-002;100.00580;1.00000
 39.47231; 1.72868;5.113413e-002;100.00679;1.00000
 39.97977; 1.87274;5.983194e-002;100.02396;1.00000
 40.52897; 2.01680;6.965703e-002;100.01806;1.00000
 41.16596; 2.16086;7.821884e-002;100.01484;1.00000
 41.84529; 2.30491;8.713210e-002;100.02340;1.00000
 42.57268; 2.44897;9.636771e-002;100.01719;1.00000
 43.33024; 2.59303;      0.10597;100.02412;1.00000
 44.15982; 2.73708;      0.11384;100.03563;1.00000
 45.03101; 2.88114;      0.12225;100.02928;1.00000
 45.90280; 3.02520;      0.13043;100.03362;1.00000
 46.84003; 3.16925;      0.13836;100.04392;1.00000
 47.81297; 3.31331;      0.14573;100.04057;1.00000
 48.81716; 3.45737;      0.15302;100.02927;1.00000
 49.85007; 3.60143;      0.16002;100.03679;1.00000
 50.91075; 3.74548;      0.16624;100.03422;1.00000
 51.97569; 3.88954;      0.17164;100.02683;1.00000
 53.08026; 4.03360;      0.17767;100.02002;1.00000
 54.22297; 4.17765;      0.18303;100.02486;1.00000
 55.35622; 4.32171;      0.18783;100.03219;1.00000
 56.52035; 4.46577;      0.19329;100.03211;1.00000
 57.71432; 4.60982;      0.19797;100.03597;1.00000
 58.92123; 4.75388;      0.20322;100.04588;1.00000
 60.13444; 4.89794;      0.20686;100.04780;1.00000
 61.35767; 5.04200;      0.21180;100.03299;1.00000
 62.60725; 5.18605;      0.21475;100.02741;1.00000
 63.86690; 5.33011;      0.21813;100.00899;1.00000
 65.15414; 5.47417;      0.22174;100.00558;1.00000
 66.42776; 5.61822;      0.22486;100.00095;1.00000
 67.71728; 5.76228;      0.22761; 99.98458;1.00000
 69.02071; 5.90634;      0.23165; 99.99072;1.00000
 70.33606; 6.05040;      0.23427; 99.99407;1.00000
 71.64536; 6.19445;      0.23720; 99.99519;1.00000
 72.97941; 6.33851;      0.24034; 99.98695;1.00000
 74.31066; 6.48257;      0.24246;100.00092;1.00000
 75.62596; 6.62662;      0.24541;100.00034;1.00000
 76.97627; 6.77068;      0.24798; 99.99003;1.00000
 78.33981; 6.91474;      0.25073; 99.97554;1.00000
 79.70127; 7.05879;      0.25317; 99.96819;1.00000
 81.06006; 7.20285;      0.25541; 99.95900;1.00000
 82.42418; 7.34691;      0.25772; 99.95985;1.00000
 83.78323; 7.49097;      0.25997; 99.95606;1.00000
 85.17400; 7.63502;      0.26144; 99.94765;1.00000
 86.56144; 7.77908;      0.26359; 99.94293;1.00000
 87.95759; 7.92314;      0.26668; 99.93689;1.00000
 89.37576; 8.06719;      0.26790; 99.94294;1.00000
 90.78356; 8.21125;      0.26977; 99.93395;1.00000
 92.21456; 8.35531;      0.27159; 99.92988;1.00000
 93.62630; 8.49936;      0.27321; 99.92509;1.00000
 95.05750; 8.64342;      0.27408; 99.90808;1.00000
 96.50415; 8.78748;      0.27559; 99.91006;1.00000
 97.93451; 8.93154;      0.27835; 99.90171;1.00000
 99.38058; 9.07559;      0.27896; 99.89304;1.00000
100.81047; 9.21965;      0.28046; 99.88704;1.00000
102.26238; 9.36371;      0.28103; 99.88752;1.00000
103.73191; 9.50776;      0.28331; 99.86614;1.00000
105.18679; 9.65182;      0.28446; 99.85589;1.00000
106.64035; 9.79588;      0.28418; 99.84513;1.00000
108.09233; 9.93993;      0.28526; 99.84200;1.00000
109.55377;10.08399;      0.28620; 99.84503;1.00000
111.01280;10.22805;      0.28671; 99.84790;1.00000
112.46802;10.37211;      0.28734; 99.83063;1.00000
113.92384;10.51616;      0.28759; 99.81701;1.00000
115.40654;10.66022;      0.28785; 99.80598;1.00000
116.85952;10.80428;      0.28735; 99.80413;1.00000
118.32402;10.94833;      0.28926; 99.80133;1.00000
119.81082;11.09239;      0.28842; 99.78596;1.00000
121.26484;11.23645;      0.28823; 99.78516;1.00000
122.73613;11.38051;      0.28890; 99.77092;1.00000
124.21561;11.52456;      0.28913; 99.75355;1.00000
125.67058;11.66862;      0.28828; 99.74400;1.00000
127.16491;11.81268;      0.28931; 99.73870;1.00000
128.64097;11.95673;      0.28904; 99.73134;1.00000
130.12607;12.10079;      0.28912; 99.72196;1.00000
131.60823;12.24485;      0.28886; 99.71678;1.00000
133.10554;12.38890;      0.28946; 99.71207;1.00000
134.60229;12.53296;      0.28865; 99.70423;1.00000
136.08752;12.67702;      0.28800; 99.69379;1.00000
137.58677;12.82108;      0.28882; 99.66394;1.00000
139.08608;12.96513;      0.28905; 99.66346;1.00000
140.58926;13.10919;      0.28854; 99.65307;1.00000
142.09700;13.25325;      0.29000; 99.64403;1.00000
143.59209;13.39730;      0.28846; 99.64312;1.00000
145.10260;13.54136;      0.28871; 99.63591;1.00000
146.61480;13.68542;      0.28926; 99.62636;1.00000
148.11956;13.82947;      0.28862; 99.60011;1.00000
149.63329;13.97353;      0.28910; 99.58480;1.00000
151.14306;14.11759;      0.28890; 99.57613;1.00000
152.65620;14.26165;      0.28945; 99.56598;1.00000
154.16655;14.40570;      0.28920; 99.55803;1.00000
155.67860;14.54976;      0.29022; 99.54206;1.00000
157.19669;14.69382;      0.29094; 99.51650;1.00000
158.71949;14.83787;      0.29078; 99.51019;1.00000
160.22665;14.98193;      0.29129; 99.50196;1.00000
161.74513;15.12599;      0.29169; 99.48087;1.00000
163.25446;15.27005;      0.29235; 99.47099;1.00000
164.76846;15.41410;      0.29298; 99.45029;1.00000
166.28463;15.55816;      0.29314; 99.43217;1.00000
167.78629;15.70222;      0.29395; 99.41685;1.00000
169.29531;15.84627;      0.29421; 99.40602;1.00000
170.81972;15.99033;      0.29444; 99.39097;1.00000
172.33639;16.13439;      0.29519; 99.37358;1.00000
173.84567;16.27844;      0.29527; 99.36012;1.00000
175.36497;16.42250;      0.29620; 99.34956;1.00000
176.87794;16.56656;      0.29615; 99.34506;1.00000
178.39220;16.71062;      0.29663; 99.33196;1.00000
179.91602;16.85467;      0.29695; 99.31861;1.00000
181.42889;16.99873;      0.29832; 99.28022;1.00000
182.95443;17.14279;      0.29832; 99.25445;1.00000
184.47579;17.28684;      0.29857; 99.23893;1.00000
185.98218;17.43090;      0.29948; 99.22894;1.00000
187.52663;17.57496;      0.30009; 99.20658;1.00000
189.04822;17.71901;      0.29991; 99.18999;1.00000
190.58378;17.86307;      0.30109; 99.18670;1.00000
192.09130;18.00713;      0.30119; 99.17838;1.00000
193.63946;18.15119;      0.30110; 99.16597;1.00000
195.18642;18.29524;      0.30281; 99.15494;1.00000
196.71562;18.43930;      0.30352; 99.13013;1.00000
198.25826;18.58336;      0.30307; 99.10059;1.00000
199.80043;18.72741;      0.30404; 99.09126;1.00000
201.33953;18.87147;      0.30466; 99.07587;1.00000
202.87946;19.01553;      0.30585; 99.05992;1.00000
204.41464;19.15958;      0.30633; 99.04104;1.00000
205.96620;19.30364;      0.30725; 99.02229;1.00000
207.51352;19.44770;      0.30695; 98.99474;1.00000
209.05823;19.59176;      0.30892; 98.96560;1.00000
210.60597;19.73581;      0.30880; 98.94531;1.00000
212.15360;19.87987;      0.30984; 98.94102;1.00000
213.70477;20.02393;      0.30968; 98.92375;1.00000
215.25498;20.16798;      0.31095; 98.90644;1.00000
216.79125;20.31204;      0.31124; 98.89289;1.00000
218.33914;20.45610;      0.31108; 98.87038;1.00000
219.88778;20.60016;      0.31242; 98.84196;1.00000
221.42984;20.74421;      0.31210; 98.81830;1.00000
222.96762;20.88827;      0.31254; 98.78834;1.00000
224.51592;21.03233;      0.31310; 98.75988;1.00000
226.04172;21.17638;      0.31267; 98.75170;1.00000
227.57651;21.32044;      0.31296; 98.71190;1.00000
229.12430;21.46450;      0.31256; 98.68876;1.00000
230.65309;21.60855;      0.31250; 98.66232;1.00000
232.18012;21.75261;      0.31223; 98.63747;1.00000
233.70399;21.89667;      0.31282; 98.61443;1.00000
235.24357;22.04073;      0.31245; 98.59597;1.00000
236.78015;22.18478;      0.31234; 98.57940;1.00000
238.31280;22.32884;      0.31198; 98.55799;1.00000
239.83913;22.47290;      0.31151; 98.53826;1.00000
241.37904;22.61695;      0.31149; 98.50637;1.00000
242.90320;22.76101;      0.31079; 98.47672;1.00000
244.42772;22.90507;      0.31060; 98.45390;1.00000
245.94554;23.04912;      0.31048; 98.44609;1.00000
247.47753;23.19318;      0.30912; 98.43039;1.00000
249.01359;23.33724;      0.30951; 98.41351;1.00000
250.53505;23.48130;      0.30822; 98.39686;1.00000
252.05831;23.62535;      0.30860; 98.37795;1.00000
253.58447;23.76941;      0.30846; 98.36506;1.00000
255.09766;23.91347;      0.30741; 98.35478;1.00000
256.62812;24.05752;      0.30731; 98.34721;1.00000
258.13332;24.20158;      0.30731; 98.33136;1.00000
259.65977;24.34564;      0.30738; 98.29849;1.00000
261.18457;24.48969;      0.30700; 98.27900;1.00000
262.69242;24.63375;      0.30625; 98.26839;1.00000
264.21313;24.77781;      0.30598; 98.24739;1.00000
265.72552;24.92187;      0.30565; 98.23065;1.00000
267.24513;25.06592;      0.30532; 98.20631;1.00000
268.76482;25.20998;      0.30365; 98.20300;1.00000
270.28446;25.35404;      0.30316; 98.19095;1.00000
271.79099;25.49809;      0.30306; 98.15810;1.00000
273.29882;25.64215;      0.30270; 98.15291;1.00000
274.81345;25.78621;      0.30306; 98.14135;1.00000
276.33849;25.93027;      0.30151; 98.12696;1.00000
277.82809;26.07432;      0.30058; 98.10666;1.00000
279.33612;26.21838;      0.29911; 98.08920;1.00000
280.84554;26.36244;      0.29737; 98.07634;1.00000
282.35584;26.50649;      0.29401; 98.04559;1.00000
283.86888;26.65055;      0.29219; 98.02791;1.00000
285.36600;26.79461;      0.29014; 98.01463;1.00000
286.86852;26.93866;      0.28890; 98.00116;1.00000
288.37002;27.08272;      0.29009; 97.99400;1.00000
289.88569;27.22678;      0.29174; 97.99027;1.00000
291.38432;27.37084;      0.29378; 97.98087;1.00000
292.89638;27.51489;      0.29656; 97.96935;1.00000
294.40429;27.65895;      0.29900; 97.95515;1.00000
295.90117;27.80301;      0.30170; 97.94774;1.00000
297.40785;27.94706;      0.30397; 97.93629;1.00000
298.89857;28.09112;      0.30473; 97.91588;1.00000
300.41636;28.23518;      0.30473; 97.90045;1.00000
301.91286;28.37923;      0.30474; 97.88102;1.00000
303.42039;28.52329;      0.30439; 97.87670;1.00000
304.91601;28.66735;      0.30488; 97.86216;1.00000
306.42138;28.81141;      0.30368; 97.84986;1.00000
307.92158;28.95546;      0.30334; 97.81038;1.00000
309.42021;29.09952;      0.30308; 97.79606;1.00000
310.92488;29.24358;      0.30374; 97.78657;1.00000
312.41895;29.38763;      0.30368; 97.77335;1.00000
313.91986;29.53169;      0.30290; 97.75991;1.00000
315.42943;29.67575;      0.30372; 97.75401;1.00000
316.92093;29.81980;      0.30495; 97.74701;1.00000
318.42486;29.96386;      0.30548; 97.73663;1.00000
319.92726;30.10792;      0.30685; 97.72423;1.00000
321.43328;30.25198;      0.30798; 97.71474;1.00000
322.92265;30.39603;      0.30887; 97.70839;1.00000
324.42292;30.54009;      0.31052; 97.70200;1.00000
325.93943;30.68415;      0.31160; 97.69801;1.00000
327.43149;30.82820;      0.31204; 97.68518;1.00000
328.93618;30.97226;      0.31161; 97.67803;1.00000
330.42656;31.11632;      0.31205; 97.66936;1.00000
331.91666;31.26038;      0.31079; 97.66197;1.00000
333.41552;31.40443;      0.31054; 97.65136;1.00000
334.91345;31.54849;      0.31051; 97.63615;1.00000
336.41235;31.69255;      0.30993; 97.62745;1.00000
337.91079;31.83660;      0.31010; 97.61043;1.00000
339.39500;31.98066;      0.30946; 97.58595;1.00000
340.90353;32.12472;      0.30992; 97.58110;1.00000
342.38934;32.26877;      0.30909; 97.56527;1.00000
343.87664;32.41283;      0.30909; 97.53631;1.00000
345.36376;32.55689;      0.30940; 97.52819;1.00000
346.84192;32.70095;      0.30843; 97.51490;1.00000
348.32264;32.84500;      0.30933; 97.50253;1.00000
349.81763;32.98906;      0.30997; 97.48711;1.00000
351.29699;33.13312;      0.31121; 97.47063;1.00000
352.79529;33.27717;      0.31084; 97.45318;1.00000
354.27664;33.42123;      0.31140; 97.43498;1.00000
355.76366;33.56529;      0.31233; 97.41722;1.00000
357.23109;33.70934;      0.31357; 97.39515;1.00000
358.72454;33.85340;      0.31450; 97.37784;1.00000
360.20461;33.99746;      0.31566; 97.36340;1.00000
361.68899;34.14152;      0.31663; 97.32585;1.00000
363.15854;34.28557;      0.31757; 97.31057;1.00000
364.64996;34.42963;      0.31829; 97.29900;1.00000
366.12128;34.57369;      0.31967; 97.29178;1.00000
367.60067;34.71774;      0.32056; 97.27922;1.00000
369.07315;34.86180;      0.32224; 97.26483;1.00000
370.55354;35.00586;      0.32227; 97.23469;1.00000
372.02319;35.14991;      0.32272; 97.22000;1.00000
373.49229;35.29397;      0.32328; 97.21060;1.00000
374.97959;35.43803;      0.32539; 97.19903;1.00000
376.44182;35.58209;      0.32528; 97.18779;1.00000
377.91173;35.72614;      0.32599; 97.17651;1.00000
379.38396;35.87020;      0.32660; 97.15998;1.00000
380.84902;36.01426;      0.32767; 97.13758;1.00000
382.32117;36.15831;      0.32929; 97.10248;1.00000
383.78963;36.30237;      0.32963; 97.06818;1.00000
385.25984;36.44643;      0.33059; 97.04747;1.00000
386.72462;36.59049;      0.33176; 97.02595;1.00000
388.20077;36.73454;      0.33281; 97.00503;1.00000
389.66896;36.87860;      0.33305; 96.98518;1.00000
391.15350;37.02266;      0.33429; 96.96771;1.00000
392.61947;37.16671;      0.33553; 96.93864;1.00000
394.09288;37.31077;      0.33694; 96.91492;1.00000
395.56194;37.45483;      0.33833; 96.89655;1.00000
397.03006;37.59888;      0.33983; 96.86522;1.00000
398.50642;37.74294;      0.34103; 96.85898;1.00000
399.96752;37.88700;      0.34199; 96.84829;1.00000
401.44828;38.03106;      0.34355; 96.82991;1.00000
402.90797;38.17511;      0.34527; 96.81114;1.00000
404.38470;38.31917;      0.34612; 96.76921;1.00000
405.84830;38.46323;      0.34735; 96.74365;1.00000
407.31545;38.60728;      0.34819; 96.72427;1.00000
408.78869;38.75134;      0.34991; 96.70471;1.00000
410.24768;38.89540;      0.35116; 96.67749;1.00000
411.70530;39.03945;      0.35331; 96.64219;1.00000
413.16993;39.18351;      0.35461; 96.62472;1.00000
414.64652;39.32757;      0.35571; 96.60436;1.00000
416.11537;39.47163;      0.35825; 96.56349;1.00000
417.56986;39.61568;      0.35961; 96.53940;1.00000
419.03447;39.75974;      0.36141; 96.51803;1.00000
420.50131;39.90380;      0.36303; 96.48505;1.00000
421.96821;40.04785;      0.36481; 96.44956;1.00000
423.42702;40.19191;      0.36635; 96.43181;1.00000
424.89867;40.33597;      0.36755; 96.39933;1.00000
426.36625;40.48003;      0.37018; 96.36099;1.00000
427.83093;40.62408;      0.37186; 96.33072;1.00000
429.30595;40.76814;      0.37441; 96.30446;1.00000
430.78243;40.91220;      0.37682; 96.27464;1.00000
432.24221;41.05625;      0.37871; 96.23575;1.00000
433.70079;41.20031;      0.38079; 96.20490;1.00000
435.15748;41.34437;      0.38282; 96.15610;1.00000
436.63333;41.48842;      0.38464; 96.11680;1.00000
438.09876;41.63248;      0.38703; 96.08761;1.00000
439.57061;41.77654;      0.38889; 96.05567;1.00000
441.02977;41.92060;      0.39234; 96.01084;1.00000
442.49305;42.06465;      0.39375; 95.97361;1.00000
443.96353;42.20871;      0.39535; 95.93552;1.00000
445.42294;42.35277;      0.39834; 95.89714;1.00000
446.87948;42.49682;      0.40213; 95.84936;1.00000
448.34807;42.64088;      0.40288; 95.79355;1.00000
449.82370;42.78494;      0.40618; 95.74000;1.00000
451.27915;42.92899;      0.40798; 95.69630;1.00000
452.76119;43.07305;      0.41014; 95.64927;1.00000
454.22586;43.21711;      0.41177; 95.60005;1.00000
455.69051;43.36117;      0.41417; 95.54279;1.00000
457.16778;43.50522;      0.41529; 95.48029;1.00000
458.63641;43.64928;      0.41790; 95.41638;1.00000
460.11903;43.79334;      0.41913; 95.35596;1.00000
461.57993;43.93739;      0.42170; 95.29591;1.00000
463.05937;44.08145;      0.42311; 95.23347;1.00000
464.52176;44.22551;      0.42519; 95.16091;1.00000
465.99536;44.36956;      0.42511; 95.09921;1.00000
467.46519;44.51362;      0.42592; 95.03480;1.00000
468.94522;44.65768;      0.42705; 94.97089;1.00000
470.41025;44.80174;      0.42735; 94.89044;1.00000
471.89955;44.94579;      0.42835; 94.81146;1.00000
473.35357;45.08985;      0.42831; 94.73700;1.00000
474.83293;45.23391;      0.42868; 94.66424;1.00000
476.30706;45.37796;      0.42892; 94.58888;1.00000
477.77035;45.52202;      0.42908; 94.49243;1.00000
479.23658;45.66608;      0.42938; 94.39501;1.00000
480.69742;45.81014;      0.42945; 94.30986;1.00000
482.16947;45.95419;      0.42930; 94.21208;1.00000
483.63276;46.09825;      0.43015; 94.12270;1.00000
485.10268;46.24231;      0.43115; 94.02225;1.00000
486.57108;46.38636;      0.43076; 93.92876;1.00000
488.03543;46.53042;      0.43228; 93.83068;1.00000
489.50194;46.67448;      0.43206; 93.72058;1.00000
490.96619;46.81853;      0.43224; 93.62527;1.00000
492.43806;46.96259;      0.43243; 93.50968;1.00000
493.91124;47.10665;      0.43339; 93.38263;1.00000
495.36999;47.25071;      0.43528; 93.25366;1.00000
496.83402;47.39476;      0.43491; 93.14315;1.00000
498.29769;47.53882;      0.43698; 93.02305;1.00000
499.75715;47.68288;      0.43807; 92.91350;1.00000
501.22001;47.82693;      0.43845; 92.80475;1.00000
502.68996;47.97099;      0.44032; 92.68369;1.00000
504.14729;48.11505;      0.44141; 92.58315;1.00000
505.60748;48.25910;      0.44235; 92.46411;1.00000
507.06565;48.40316;      0.44391; 92.34875;1.00000
508.53364;48.54722;      0.44564; 92.22757;1.00000
509.98837;48.69128;      0.44679; 92.10573;1.00000
511.44177;48.83533;      0.44872; 91.97504;1.00000
512.90607;48.97939;      0.45042; 91.86549;1.00000
514.36184;49.12345;      0.45193; 91.75427;1.00000
515.81987;49.26750;      0.45451; 91.63334;1.00000
517.28229;49.41156;      0.45673; 91.50684;1.00000
518.72055;49.55562;      0.45854; 91.38311;1.00000
520.19166;49.69967;      0.46174; 91.25152;1.00000
521.63763;49.84373;      0.46315; 91.13871;1.00000
523.09440;49.98779;      0.46572; 91.01232;1.00000
524.54549;50.13185;      0.46807; 90.89361;1.00000
525.99621;50.27590;      0.47025; 90.77623;1.00000
527.45055;50.41996;      0.47378; 90.65204;1.00000
528.90892;50.56402;      0.47509; 90.53085;1.00000
530.36543;50.70807;      0.47805; 90.42875;1.00000
531.81287;50.85213;      0.48159; 90.32337;1.00000
533.26918;50.99619;      0.48385; 90.21537;1.00000
534.72062;51.14025;      0.48546; 90.11486;1.00000
536.17186;51.28430;      0.48830; 90.00073;1.00000
537.63159;51.42836;      0.49100; 89.88468;1.00000
539.08967;51.57242;      0.49314; 89.79950;1.00000
540.53749;51.71647;      0.49572; 89.70736;1.00000
541.98210;51.86053;      0.49783; 89.60870;1.00000
543.44036;52.00459;      0.50093; 89.51712;1.00000
544.88434;52.14864;      0.50290; 89.43166;1.00000
546.34688;52.29270;      0.50500; 89.34880;1.00000
547.78893;52.43676;      0.50715; 89.26346;1.00000
549.23089;52.58082;      0.50986; 89.18860;1.00000
550.68104;52.72487;      0.51235; 89.10444;1.00000
552.12290;52.86893;      0.51461; 89.02310;1.00000
553.56577;53.01299;      0.51618; 88.95361;1.00000
555.02105;53.15704;      0.51830; 88.89323;1.00000
556.46635;53.30110;      0.52022; 88.82069;1.00000
557.89887;53.44516;      0.52205; 88.73648;1.00000
559.34444;53.58921;      0.52498; 88.66534;1.00000
560.79379;53.73327;      0.52649; 88.58664;1.00000
562.23567;53.87733;      0.52780; 88.50623;1.00000
563.68879;54.02139;      0.52987; 88.44720;1.00000
565.12768;54.16544;      0.53201; 88.37204;1.00000
566.56980;54.30950;      0.53327; 88.29733;1.00000
568.00749;54.45356;      0.53536; 88.24042;1.00000
569.45183;54.59761;      0.53848; 88.16101;1.00000
570.90269;54.74167;      0.54000; 88.08922;1.00000
572.34791;54.88573;      0.54173; 88.02157;1.00000
573.78088;55.02978;      0.54366; 87.96309;1.00000
575.22931;55.17384;      0.54552; 87.90048;1.00000
576.67623;55.31790;      0.54723; 87.86175;1.00000
578.11753;55.46196;      0.54914; 87.81250;1.00000
579.56638;55.60601;      0.55145; 87.76140;1.00000
581.00665;55.75007;      0.55435; 87.71998;1.00000
582.45104;55.89413;      0.55613; 87.66563;1.00000
583.89032;56.03818;      0.55740; 87.61642;1.00000
585.34416;56.18224;      0.55984; 87.56842;1.00000
586.78214;56.32630;      0.56203; 87.51713;1.00000
588.21961;56.47036;      0.56457; 87.46378;1.00000
589.67359;56.61441;      0.56607; 87.40698;1.00000
591.11185;56.75847;      0.56743; 87.35646;1.00000
592.54688;56.90253;      0.57038; 87.30416;1.00000
593.98377;57.04658;      0.57375; 87.25424;1.00000
595.42458;57.19064;      0.57519; 87.20192;1.00000
596.85724;57.33470;      0.57770; 87.16261;1.00000
598.30550;57.47875;      0.58019; 87.10947;1.00000
599.73619;57.62281;      0.58212; 87.05414;1.00000
601.17407;57.76687;      0.58494; 87.00589;1.00000
602.62386;57.91093;      0.58725; 86.95065;1.00000
604.06106;58.05498;      0.58935; 86.89925;1.00000
605.48533;58.19904;      0.59103; 86.85644;1.00000
606.92738;58.34310;      0.59309; 86.80074;1.00000
608.37298;58.48715;      0.59511; 86.75287;1.00000
609.79873;58.63121;      0.59730; 86.70569;1.00000
611.23594;58.77527;      0.59955; 86.66042;1.00000
612.67898;58.91932;      0.60283; 86.60625;1.00000
614.12813;59.06338;      0.60465; 86.56140;1.00000
615.57144;59.20744;      0.60697; 86.51535;1.00000
617.01495;59.35150;      0.60960; 86.47267;1.00000
618.46410;59.49555;      0.61200; 86.42791;1.00000
619.91243;59.63961;      0.61342; 86.37609;1.00000
621.35182;59.78367;      0.61658; 86.32546;1.00000
622.79564;59.92772;      0.61921; 86.28664;1.00000
624.23607;60.07178;      0.62175; 86.24592;1.00000
625.67975;60.21584;      0.62515; 86.22144;1.00000
627.11893;60.35989;      0.62821; 86.17902;1.00000
628.55983;60.50395;      0.63021; 86.13896;1.00000
630.00728;60.64801;      0.63339; 86.09156;1.00000
631.44588;60.79207;      0.63499; 86.04958;1.00000
632.87041;60.93612;      0.63746; 86.01451;1.00000
634.31778;61.08018;      0.63959; 85.97197;1.00000
635.74826;61.22424;      0.64261; 85.93213;1.00000
637.19649;61.36829;      0.64585; 85.89338;1.00000
638.60707;61.51235;      0.64740; 85.85864;1.00000
640.04020;61.65641;      0.65083; 85.81979;1.00000
641.47593;61.80047;      0.65163; 85.79191;1.00000
642.90641;61.94452;      0.65413; 85.75164;1.00000
644.33300;62.08858;      0.65694; 85.71149;1.00000
645.80816;62.23264;      0.66010; 85.66880;1.00000
647.24458;62.37669;      0.66218; 85.64264;1.00000
648.68628;62.52075;      0.66458; 85.60381;1.00000
650.11730;62.66481;      0.66585; 85.56491;1.00000
651.54872;62.80886;      0.66831; 85.52154;1.00000
652.98935;62.95292;      0.67050; 85.48915;1.00000
654.42959;63.09698;      0.67220; 85.45258;1.00000
655.85315;63.24104;      0.67411; 85.42173;1.00000
657.29225;63.38509;      0.67573; 85.37906;1.00000
658.72918;63.52915;      0.67681; 85.34119;1.00000
660.17152;63.67321;      0.68009; 85.30564;1.00000
661.60926;63.81726;      0.68189; 85.27459;1.00000
663.03426;63.96132;      0.68365; 85.22032;1.00000
664.47871;64.10538;      0.68482; 85.18439;1.00000
665.90871;64.24943;      0.68669; 85.14318;1.00000
667.34501;64.39349;      0.68819; 85.10724;1.00000
668.79771;64.53755;      0.69049; 85.07826;1.00000
670.22346;64.68161;      0.69143; 85.04751;1.00000
671.65169;64.82566;      0.69245; 85.00990;1.00000
673.08427;64.96972;      0.69465; 84.97507;1.00000
674.52256;65.11378;      0.69609; 84.93164;1.00000
675.95017;65.25783;      0.69671; 84.90711;1.00000
677.39122;65.40189;      0.69872; 84.88309;1.00000
678.81952;65.54595;      0.69911; 84.83972;1.00000
680.26006;65.69001;      0.70046; 84.79800;1.00000
681.68921;65.83406;      0.70176; 84.77849;1.00000
683.12238;65.97812;      0.70220; 84.74641;1.00000
684.55532;66.12218;      0.70307; 84.71164;1.00000
685.98565;66.26623;      0.70438; 84.68232;1.00000
687.42195;66.41029;      0.70533; 84.65194;1.00000
688.85434;66.55435;      0.70683; 84.61453;1.00000
690.30375;66.69840;      0.70662; 84.58157;1.00000
691.72350;66.84246;      0.70745; 84.53728;1.00000
693.15410;66.98652;      0.70888; 84.50193;1.00000
694.60082;67.13058;      0.70964; 84.46093;1.00000
696.02840;67.27463;      0.71009; 84.43773;1.00000
697.46274;67.41869;      0.71142; 84.39852;1.00000
698.89760;67.56275;      0.71037; 84.37150;1.00000
700.32641;67.70680;      0.71248; 84.34730;1.00000
701.74848;67.85086;      0.71233; 84.31398;1.00000
703.18102;67.99492;      0.71188; 84.28707;1.00000
704.62412;68.13897;      0.71220; 84.24924;1.00000
706.05135;68.28303;      0.71198; 84.21643;1.00000
707.49853;68.42709;      0.71194; 84.17147;1.00000
708.93198;68.57115;      0.71067; 84.14764;1.00000
710.35889;68.71520;      0.71118; 84.11052;1.00000
711.80508;68.85926;      0.71046; 84.07622;1.00000
713.22948;69.00332;      0.71065; 84.03724;1.00000
714.65796;69.14737;      0.71029; 84.00751;1.00000
716.10241;69.29143;      0.71010; 83.95061;1.00000
717.53644;69.43549;      0.70878; 83.91023;1.00000
718.97944;69.57954;      0.70839; 83.85706;1.00000
720.40785;69.72360;      0.70716; 83.82055;1.00000
721.83612;69.86766;      0.70632; 83.78063;1.00000
723.27921;70.01172;      0.70626; 83.75676;1.00000
724.71400;70.15577;      0.70452; 83.74642;1.00000
726.14624;70.29983;      0.70404; 83.70804;1.00000
727.57132;70.44389;      0.70281; 83.68119;1.00000
729.00393;70.58794;      0.70224; 83.64466;1.00000
730.42205;70.73200;      0.70020; 83.60534;1.00000
731.85215;70.87606;      0.69872; 83.57462;1.00000
733.27815;71.02012;      0.69693; 83.54098;1.00000
734.70733;71.16417;      0.69489; 83.51957;1.00000
736.14216;71.30823;      0.69260; 83.49026;1.00000
737.55094;71.45229;      0.68954; 83.46344;1.00000
738.98450;71.59634;      0.68764; 83.42708;1.00000
740.40977;71.74040;      0.68639; 83.39295;1.00000
741.84017;71.88446;      0.68284; 83.36716;1.00000
743.26826;72.02851;      0.68275; 83.34229;1.00000
744.69312;72.17257;      0.68127; 83.31529;1.00000
746.12203;72.31663;      0.68014; 83.28667;1.00000
747.55077;72.46069;      0.67803; 83.24086;1.00000
748.98638;72.60474;      0.67559; 83.20244;1.00000
750.40585;72.74880;      0.67414; 83.17324;1.00000
751.83324;72.89286;      0.67272; 83.14051;1.00000
753.25748;73.03691;      0.67085; 83.10190;1.00000
754.68195;73.18097;      0.66806; 83.05882;1.00000
756.10321;73.32503;      0.66579; 83.01398;1.00000
757.53589;73.46908;      0.66474; 82.98515;1.00000
758.96218;73.61314;      0.66304; 82.95337;1.00000
760.38587;73.75720;      0.66111; 82.91644;1.00000
761.80813;73.90126;      0.65898; 82.90778;1.00000
763.23316;74.04531;      0.65825; 82.88183;1.00000
764.65469;74.18937;      0.65523; 82.86512;1.00000
766.08272;74.33343;      0.65402; 82.82318;1.00000
767.50010;74.47748;      0.65240; 82.79052;1.00000
768.92950;74.62154;      0.65020; 82.75875;1.00000
770.35308;74.76560;      0.64821; 82.73130;1.00000
771.76575;74.90965;      0.64714; 82.70900;1.00000
773.18754;75.05371;      0.64523; 82.69457;1.00000
774.60817;75.19777;      0.64261; 82.67759;1.00000
776.03497;75.34183;      0.64135; 82.65154;1.00000
777.45354;75.48588;      0.64052; 82.61595;1.00000
778.88336;75.62994;      0.63934; 82.60202;1.00000
780.31302;75.77400;      0.63938; 82.57061;1.00000
781.73157;75.91805;      0.63818; 82.54058;1.00000
783.17168;76.06211;      0.63856; 82.51362;1.00000
784.58586;76.20617;      0.63812; 82.49538;1.00000
786.01324;76.35023;      0.63668; 82.47997;1.00000
787.44950;76.49428;      0.63727; 82.44539;1.00000
788.88105;76.63834;      0.63571; 82.43054;1.00000
790.31036;76.78240;      0.63488; 82.39425;1.00000
791.74320;76.92645;      0.63512; 82.36204;1.00000
793.17152;77.07051;      0.63382; 82.33292;1.00000
794.59396;77.21457;      0.63240; 82.31244;1.00000
796.02994;77.35862;      0.63171; 82.27920;1.00000
797.45400;77.50268;      0.63055; 82.27371;1.00000
798.88880;77.64674;      0.62952; 82.25732;1.00000
800.30247;77.79080;      0.62917; 82.23985;1.00000
801.72225;77.93485;      0.62819; 82.22347;1.00000
803.14192;78.07891;      0.62875; 82.20115;1.00000
804.56428;78.22297;      0.62831; 82.18439;1.00000
805.97872;78.36702;      0.62798; 82.16067;1.00000
807.38786;78.51108;      0.62907; 82.13693;1.00000
808.80698;78.65514;      0.62829; 82.10393;1.00000
810.22090;78.79919;      0.62787; 82.09211;1.00000
811.63443;78.94325;      0.62633; 82.07032;1.00000
813.04536;79.08731;      0.62533; 82.04516;1.00000
814.46055;79.23137;      0.62471; 82.02484;1.00000
815.87493;79.37542;      0.62457; 82.00493;1.00000
817.29552;79.51948;      0.62440; 81.99205;1.00000
818.71948;79.66354;      0.62342; 81.97832;1.00000
820.14420;79.80759;      0.62269; 81.95843;1.00000
821.55775;79.95165;      0.62204; 81.93883;1.00000
822.98864;80.09571;      0.62187; 81.91830;1.00000
824.41366;80.23976;      0.62143; 81.89405;1.00000
825.84059;80.38382;      0.62091; 81.88159;1.00000
827.25804;80.52788;      0.62075; 81.86425;1.00000
828.69350;80.67194;      0.62064; 81.84598;1.00000
830.11873;80.81599;      0.62087; 81.83450;1.00000
831.55153;80.96005;      0.62012; 81.82900;1.00000
832.97995;81.10411;      0.62121; 81.82169;1.00000
834.40416;81.24816;      0.62134; 81.81896;1.00000
835.82658;81.39222;      0.62065; 81.81470;1.00000
837.24838;81.53628;      0.62157; 81.79899;1.00000
838.66012;81.68034;      0.62202; 81.77489;1.00000
840.08790;81.82439;      0.62292; 81.75255;1.00000
841.50231;81.96845;      0.62306; 81.73031;1.00000
842.92576;82.11251;      0.62326; 81.70454;1.00000
844.34565;82.25656;      0.62261; 81.69194;1.00000
845.77173;82.40062;      0.62372; 81.67496;1.00000
847.19843;82.54468;      0.62324; 81.66398;1.00000
848.61096;82.68873;      0.62450; 81.64514;1.00000
850.02618;82.83279;      0.62471; 81.63692;1.00000
851.44514;82.97685;      0.62601; 81.62721;1.00000
852.85542;83.12091;      0.62682; 81.61998;1.00000
854.27232;83.26496;      0.62763; 81.61251;1.00000
855.69505;83.40902;      0.62728; 81.59808;1.00000
857.11358;83.55308;      0.62882; 81.57728;1.00000
858.53509;83.69713;      0.62981; 81.55900;1.00000
859.95940;83.84119;      0.62900; 81.54689;1.00000
861.37245;83.98525;      0.63022; 81.54036;1.00000
862.79859;84.12930;      0.63086; 81.53598;1.00000
864.21530;84.27336;      0.63041; 81.51325;1.00000
865.63867;84.41742;      0.63134; 81.49140;1.00000
867.06046;84.56148;      0.63265; 81.46968;1.00000
868.48043;84.70553;      0.63276; 81.44888;1.00000
869.90280;84.84959;      0.63453; 81.44102;1.00000
871.32584;84.99365;      0.63440; 81.43175;1.00000
872.74627;85.13770;      0.63564; 81.40122;1.00000
874.16221;85.28176;      0.63576; 81.39382;1.00000
875.58110;85.42582;      0.63686; 81.38088;1.00000
877.00969;85.56987;      0.63736; 81.37900;1.00000
878.43721;85.71393;      0.63809; 81.36960;1.00000
879.86615;85.85799;      0.63930; 81.35401;1.00000
881.29720;86.00205;      0.63944; 81.35101;1.00000
882.72728;86.14610;      0.64037; 81.34640;1.00000
884.15973;86.29016;      0.64156; 81.33297;1.00000
885.58173;86.43422;      0.64354; 81.32282;1.00000
887.01102;86.57827;      0.64536; 81.31801;1.00000
888.42269;86.72233;      0.64586; 81.31305;1.00000
889.84836;86.86639;      0.64798; 81.30236;1.00000
891.26763;87.01045;      0.64918; 81.29298;1.00000
892.68908;87.15450;      0.65039; 81.27854;1.00000
894.10472;87.29856;      0.65083; 81.26612;1.00000
895.52533;87.44262;      0.65253; 81.26935;1.00000
896.94754;87.58667;      0.65398; 81.27369;1.00000
898.36963;87.73073;      0.65529; 81.26592;1.00000
899.78293;87.87479;      0.65687; 81.25893;1.00000
901.20750;88.01884;      0.65794; 81.26198;1.00000
902.62024;88.16290;      0.65845; 81.25550;1.00000
904.04574;88.30696;      0.65935; 81.24426;1.00000
905.47392;88.45102;      0.66150; 81.24400;1.00000
906.89801;88.59507;      0.66252; 81.24014;1.00000
908.32486;88.73913;      0.66384; 81.23016;1.00000
909.75049;88.88319;      0.66711; 81.20858;1.00000
911.16327;89.02724;      0.66862; 81.18818;1.00000
912.57974;89.17130;      0.67107; 81.17185;1.00000
914.00131;89.31536;      0.67166; 81.16568;1.00000
915.41923;89.45941;      0.67381; 81.15502;1.00000
916.83720;89.60347;      0.67472; 81.14464;1.00000
918.25458;89.74753;      0.67695; 81.12882;1.00000
919.68350;89.89159;      0.67868; 81.11511;1.00000
921.10617;90.03564;      0.68024; 81.10752;1.00000
922.52120;90.17970;      0.68218; 81.09802;1.00000
923.95455;90.32376;      0.68414; 81.08979;1.00000
925.37682;90.46781;      0.68546; 81.09211;1.00000
926.79898;90.61187;      0.68820; 81.08510;1.00000
928.23296;90.75593;      0.68970; 81.08816;1.00000
929.64988;90.89998;      0.69153; 81.06600;1.00000
931.07562;91.04404;      0.69271; 81.06503;1.00000
932.49435;91.18810;      0.69527; 81.05402;1.00000
933.91783;91.33216;      0.69775; 81.05382;1.00000
935.33490;91.47621;      0.70066; 81.04845;1.00000
936.75740;91.62027;      0.70192; 81.05101;1.00000
938.18470;91.76433;      0.70433; 81.04102;1.00000
939.60207;91.90838;      0.70587; 81.03210;1.00000
941.03174;92.05244;      0.70710; 81.01974;1.00000
942.46134;92.19650;      0.70932; 81.00330;1.00000
943.89083;92.34056;      0.71087; 81.00197;1.00000
945.32008;92.48461;      0.71350; 80.99299;1.00000
946.73538;92.62867;      0.71545; 80.98415;1.00000
948.16699;92.77273;      0.71734; 80.96692;1.00000
949.58801;92.91678;      0.71984; 80.95413;1.00000
951.00762;93.06084;      0.72280; 80.95400;1.00000
952.42472;93.20490;      0.72466; 80.95416;1.00000
953.84087;93.34895;      0.72666; 80.94020;1.00000
955.26873;93.49301;      0.72899; 80.92429;1.00000
956.68651;93.63707;      0.73109; 80.92500;1.00000
958.10527;93.78113;      0.73363; 80.92496;1.00000
959.52529;93.92518;      0.73659; 80.92110;1.00000
960.94009;94.06924;      0.73834; 80.92400;1.00000
962.35202;94.21330;      0.74076; 80.92810;1.00000
963.77344;94.35735;      0.74264; 80.92221;1.00000
965.19078;94.50141;      0.74549; 80.91398;1.00000
966.60698;94.64547;      0.74806; 80.90860;1.00000
968.02634;94.78952;      0.74927; 80.90104;1.00000
969.44816;94.93358;      0.75072; 80.88367;1.00000
970.88137;95.07764;      0.75310; 80.87170;1.00000
972.29479;95.22170;      0.75465; 80.87298;1.00000
973.71115;95.36575;      0.75584; 80.86568;1.00000
975.12225;95.50981;      0.75997; 80.85404;1.00000
976.55369;95.65387;      0.76041; 80.83925;1.00000
977.97281;95.79792;      0.76199; 80.82721;1.00000
979.39179;95.94198;      0.76460; 80.81676;1.00000
979.87097;95.99000;      0.76508; 80.81500;1.00000