File: tgms/tgms/ExpDat_TL2V(20K)Ar-TG.txt
#EXPORTTYPE:DATA SINGLE
#FILE:TL2V(20K)Ar.ngb-ds3
#FORMAT:NETZSCH5
#FTYPE:ANSI
#IDENTITY:005
#DECIMAL:POINT
#SEPARATOR:SEMICOLON
#MTYPE:TG
#INSTRUMENT:NETZSCH STA 449F3
#PROJECT:调试
#DATE/TIME:14.09.2018 12:19
#CORR. FILE:Baseline-1200Ar.ngb-bs3
#TEMPCAL:TCALZERO.TCX
#SENSITIVITY:---
#LABORATORY:煤及煤系气重点实验室
#OPERATOR:wangchg
#REMARK:
#SAMPLE:TL2V(20K)Ar
#SAMPLE MASS /mg:132.5973
#MATERIAL:煤样
#REFERENCE:
#REFERENCE MASS /mg:
#TYPE OF CRUCIBLE:Plate
#SAMPLE CRUCIBLE MASS /mg:0.0
#REFERENCE CRUCIBLE MASS /mg:
#TG RANGE /mg:35000
#TAU-R:---
#CORR. CODE:020
#EXO:-1
#RANGE:45°C/20.0(K/min)/1200°C
#SEGMENT:S1/1
#SEG. 1:45°C/20.0(K/min)/1200°C

##Temp./°C;Time/min;Mass/%
  39.62600; 0.00000;100.00000
  40.74340; 1.23543;100.00346
  41.86080; 1.53659;100.00384
  42.97820; 1.76104;100.00364
  44.09560; 1.94567;100.00012
  45.21300; 2.10793; 99.99779
  46.33040; 2.25436; 99.99698
  47.44780; 2.38945; 99.99514
  48.56520; 2.51613; 99.99457
  49.68260; 2.63552; 99.99327
  50.80000; 2.74795; 99.99133
  51.91740; 2.85651; 99.99038
  53.03480; 2.96060; 99.98868
  54.15220; 3.06122; 99.98633
  55.26960; 3.15835; 99.98451
  56.38700; 3.25306; 99.98196
  57.50440; 3.34536; 99.98068
  58.62180; 3.43524; 99.97699
  59.73919; 3.52298; 99.97480
  60.85659; 3.60915; 99.97287
  61.97399; 3.69329; 99.96980
  63.09139; 3.77584; 99.96833
  64.20879; 3.85743; 99.96735
  65.32619; 3.93761; 99.96489
  66.44359; 4.01637; 99.96236
  67.56099; 4.09417; 99.95936
  68.67839; 4.17131; 99.95708
  69.79579; 4.24717; 99.95373
  70.91319; 4.32234; 99.95233
  72.03059; 4.39695; 99.95024
  73.14799; 4.47032; 99.94796
  74.26539; 4.54305; 99.94521
  75.38279; 4.61530; 99.94267
  76.50019; 4.68713; 99.94039
  77.61759; 4.75790; 99.93786
  78.73499; 4.82816; 99.93509
  79.85239; 4.89795; 99.93246
  80.96979; 4.96684; 99.92963
  82.08719; 5.03574; 99.92749
  83.20459; 5.10363; 99.92473
  84.32199; 5.17105; 99.92252
  85.43939; 5.23790; 99.92118
  86.55679; 5.30422; 99.91917
  87.67419; 5.37019; 99.91719
  88.79159; 5.43570; 99.91499
  89.90899; 5.50086; 99.91317
  91.02639; 5.56510; 99.91085
  92.14379; 5.62918; 99.90811
  93.26119; 5.69307; 99.90518
  94.37859; 5.75648; 99.90366
  95.49599; 5.81976; 99.90181
  96.61339; 5.88254; 99.89985
  97.73079; 5.94502; 99.89819
  98.84819; 6.00725; 99.89654
  99.96559; 6.06912; 99.89474
 101.08299; 6.13087; 99.89319
 102.20038; 6.19258; 99.89124
 103.31778; 6.25428; 99.88828
 104.43518; 6.31552; 99.88566
 105.55258; 6.37643; 99.88498
 106.66998; 6.43718; 99.88356
 107.78738; 6.49790; 99.88197
 108.90478; 6.55838; 99.88029
 110.02218; 6.61877; 99.87825
 111.13958; 6.67867; 99.87589
 112.25698; 6.73859; 99.87426
 113.37438; 6.79849; 99.87268
 114.49178; 6.85813; 99.87071
 115.60918; 6.91760; 99.86901
 116.72658; 6.97667; 99.86739
 117.84398; 7.03568; 99.86542
 118.96138; 7.09448; 99.86328
 120.07878; 7.15304; 99.86232
 121.19618; 7.21133; 99.86120
 122.31358; 7.26957; 99.85958
 123.43098; 7.32771; 99.85749
 124.54838; 7.38540; 99.85610
 125.66578; 7.44279; 99.85490
 126.78318; 7.50042; 99.85346
 127.90058; 7.55794; 99.85218
 129.01798; 7.61499; 99.85068
 130.13538; 7.67224; 99.84884
 131.25278; 7.72909; 99.84716
 132.37018; 7.78585; 99.84544
 133.48758; 7.84241; 99.84390
 134.60498; 7.89860; 99.84225
 135.72238; 7.95455; 99.84058
 136.83978; 8.01073; 99.83896
 137.95718; 8.06680; 99.83714
 139.07458; 8.12245; 99.83601
 140.19198; 8.17816; 99.83457
 141.30938; 8.23379; 99.83281
 142.42678; 8.28918; 99.83153
 143.54418; 8.34436; 99.82973
 144.66158; 8.39949; 99.82807
 145.77897; 8.45452; 99.82611
 146.89637; 8.50941; 99.82386
 148.01377; 8.56417; 99.82159
 149.13117; 8.61861; 99.81965
 150.24857; 8.67328; 99.81762
 151.36597; 8.72796; 99.81532
 152.48337; 8.78246; 99.81262
 153.60077; 8.83682; 99.81077
 154.71817; 8.89102; 99.80811
 155.83557; 8.94524; 99.80617
 156.95297; 8.99922; 99.80412
 158.07037; 9.05311; 99.80181
 159.18777; 9.10715; 99.80001
 160.30517; 9.16122; 99.79784
 161.42257; 9.21510; 99.79554
 162.53997; 9.26910; 99.79263
 163.65737; 9.32290; 99.79063
 164.77477; 9.37648; 99.78831
 165.89217; 9.43017; 99.78663
 167.00957; 9.48376; 99.78421
 168.12697; 9.53707; 99.78143
 169.24437; 9.59049; 99.77819
 170.36177; 9.64412; 99.77591
 171.47917; 9.69749; 99.77359
 172.59657; 9.75071; 99.77073
 173.71397; 9.80405; 99.76742
 174.83137; 9.85735; 99.76509
 175.94877; 9.91033; 99.76121
 177.06617; 9.96314; 99.75936
 178.18357;10.01610; 99.75719
 179.30097;10.06886; 99.75480
 180.41837;10.12138; 99.75151
 181.53577;10.17392; 99.74863
 182.65317;10.22654; 99.74591
 183.77057;10.27903; 99.74325
 184.88797;10.33145; 99.74018
 186.00537;10.38384; 99.73700
 187.12277;10.43610; 99.73385
 188.24017;10.48837; 99.73163
 189.35756;10.54057; 99.72829
 190.47496;10.59276; 99.72506
 191.59236;10.64525; 99.72145
 192.70976;10.69793; 99.71879
 193.82716;10.75041; 99.71500
 194.94456;10.80274; 99.71233
 196.06196;10.85487; 99.70899
 197.17936;10.90676; 99.70610
 198.29676;10.95865; 99.70267
 199.41416;11.01069; 99.69901
 200.53156;11.06274; 99.69518
 201.64896;11.11474; 99.69028
 202.76636;11.16683; 99.68730
 203.88376;11.21877; 99.68353
 205.00116;11.27073; 99.67866
 206.11856;11.32278; 99.67526
 207.23596;11.37466; 99.67152
 208.35336;11.42646; 99.66777
 209.47076;11.47814; 99.66393
 210.58816;11.52999; 99.66070
 211.70556;11.58196; 99.65735
 212.82296;11.63386; 99.65263
 213.94036;11.68558; 99.64950
 215.05776;11.73732; 99.64468
 216.17516;11.78915; 99.64095
 217.29256;11.84108; 99.63679
 218.40996;11.89286; 99.63212
 219.52736;11.94454; 99.62748
 220.64476;11.99638; 99.62283
 221.76216;12.04817; 99.61729
 222.87956;12.09988; 99.61274
 223.99696;12.15148; 99.60817
 225.11436;12.20320; 99.60313
 226.23176;12.25522; 99.59808
 227.34916;12.30723; 99.59246
 228.46656;12.35905; 99.58782
 229.58396;12.41093; 99.58233
 230.70136;12.46276; 99.57622
 231.81875;12.51432; 99.57150
 232.93615;12.56598; 99.56549
 234.05355;12.61768; 99.55950
 235.17095;12.66925; 99.55324
 236.28835;12.72082; 99.54858
 237.40575;12.77247; 99.54327
 238.52315;12.82411; 99.53719
 239.64055;12.87564; 99.53116
 240.75795;12.92728; 99.52467
 241.87535;12.97926; 99.51854
 242.99275;13.03150; 99.51190
 244.11015;13.08345; 99.50602
 245.22755;13.13515; 99.49938
 246.34495;13.18689; 99.49332
 247.46235;13.23875; 99.48722
 248.57975;13.29067; 99.48107
 249.69715;13.34258; 99.47455
 250.81455;13.39462; 99.46760
 251.93195;13.44670; 99.46059
 253.04935;13.49878; 99.45390
 254.16675;13.55105; 99.44678
 255.28415;13.60333; 99.43981
 256.40155;13.65535; 99.43221
 257.51895;13.70723; 99.42497
 258.63635;13.75914; 99.41747
 259.75375;13.81103; 99.41023
 260.87115;13.86290; 99.40308
 261.98855;13.91469; 99.39557
 263.10595;13.96649; 99.38830
 264.22335;14.01837; 99.38097
 265.34075;14.07034; 99.37287
 266.45815;14.12235; 99.36477
 267.57555;14.17436; 99.35623
 268.69295;14.22632; 99.34838
 269.81035;14.27818; 99.34035
 270.92775;14.33018; 99.33184
 272.04515;14.38231; 99.32309
 273.16255;14.43437; 99.31414
 274.27995;14.48636; 99.30495
 275.39734;14.53850; 99.29551
 276.51474;14.59081; 99.28604
 277.63214;14.64323; 99.27670
 278.74954;14.69567; 99.26776
 279.86694;14.74785; 99.25841
 280.98434;14.79994; 99.24811
 282.10174;14.85222; 99.23856
 283.21914;14.90463; 99.22894
 284.33654;14.95683; 99.21865
 285.45394;15.00897; 99.20809
 286.57134;15.06144; 99.19588
 287.68874;15.11398; 99.18413
 288.80614;15.16619; 99.17224
 289.92354;15.21838; 99.16144
 291.04094;15.27086; 99.15028
 292.15834;15.32315; 99.13914
 293.27574;15.37542; 99.12777
 294.39314;15.42794; 99.11697
 295.51054;15.48034; 99.10481
 296.62794;15.53282; 99.09327
 297.74534;15.58535; 99.08175
 298.86274;15.63783; 99.06903
 299.98014;15.69038; 99.05632
 301.09754;15.74293; 99.04387
 302.21494;15.79556; 99.03221
 303.33234;15.84817; 99.02019
 304.44974;15.90069; 99.00753
 305.56714;15.95324; 98.99462
 306.68454;16.00586; 98.97980
 307.80194;16.05845; 98.96519
 308.91934;16.11111; 98.95134
 310.03674;16.16383; 98.93799
 311.15414;16.21645; 98.92567
 312.27154;16.26904; 98.91277
 313.38894;16.32168; 98.89982
 314.50634;16.37444; 98.88509
 315.62374;16.42720; 98.86991
 316.74114;16.47996; 98.85587
 317.85854;16.53269; 98.84098
 318.97593;16.58547; 98.82589
 320.09333;16.63835; 98.81119
 321.21073;16.69125; 98.79691
 322.32813;16.74417; 98.78116
 323.44553;16.79697; 98.76610
 324.56293;16.84979; 98.75012
 325.68033;16.90268; 98.73433
 326.79773;16.95567; 98.71869
 327.91513;17.00867; 98.70363
 329.03253;17.06168; 98.68766
 330.14993;17.11472; 98.67103
 331.26733;17.16793; 98.65380
 332.38473;17.22127; 98.63746
 333.50213;17.27436; 98.62135
 334.61953;17.32737; 98.60478
 335.73693;17.38047; 98.58705
 336.85433;17.43341; 98.57021
 337.97173;17.48604; 98.55323
 339.08913;17.53884; 98.53586
 340.20653;17.59185; 98.51795
 341.32393;17.64502; 98.49958
 342.44133;17.69847; 98.48074
 343.55873;17.75192; 98.46143
 344.67613;17.80515; 98.44245
 345.79353;17.85835; 98.42266
 346.91093;17.91170; 98.40194
 348.02833;17.96505; 98.38102
 349.14573;18.01837; 98.36033
 350.26313;18.07180; 98.33916
 351.38053;18.12522; 98.31873
 352.49793;18.17863; 98.29690
 353.61533;18.23202; 98.27598
 354.73273;18.28542; 98.25341
 355.85013;18.33880; 98.23117
 356.96753;18.39226; 98.20847
 358.08493;18.44582; 98.18481
 359.20233;18.49937; 98.16149
 360.31973;18.55294; 98.13709
 361.43712;18.60640; 98.11329
 362.55452;18.65988; 98.08841
 363.67192;18.71353; 98.06351
 364.78932;18.76707; 98.03787
 365.90672;18.82063; 98.01235
 367.02412;18.87427; 97.98537
 368.14152;18.92783; 97.95932
 369.25892;18.98137; 97.93322
 370.37632;19.03501; 97.90621
 371.49372;19.08863; 97.87840
 372.61112;19.14227; 97.85043
 373.72852;19.19594; 97.82238
 374.84592;19.24962; 97.79348
 375.96332;19.30343; 97.76368
 377.08072;19.35721; 97.73473
 378.19812;19.41094; 97.70512
 379.31552;19.46459; 97.67581
 380.43292;19.51824; 97.64559
 381.55032;19.57205; 97.61516
 382.66772;19.62580; 97.58472
 383.78512;19.67955; 97.55436
 384.90252;19.73333; 97.52269
 386.01992;19.78696; 97.49143
 387.13732;19.84065; 97.45918
 388.25472;19.89443; 97.42744
 389.37212;19.94815; 97.39565
 390.48952;20.00193; 97.36290
 391.60692;20.05566; 97.33003
 392.72432;20.10938; 97.29707
 393.84172;20.16320; 97.26349
 394.95912;20.21707; 97.23073
 396.07652;20.27091; 97.19754
 397.19392;20.32458; 97.16499
 398.31132;20.37816; 97.13130
 399.42872;20.43184; 97.09814
 400.54612;20.48555; 97.06419
 401.66352;20.53931; 97.03036
 402.78092;20.59301; 96.99549
 403.89832;20.64677; 96.96128
 405.01571;20.70040; 96.92727
 406.13311;20.75397; 96.89313
 407.25051;20.80769; 96.85799
 408.36791;20.86135; 96.82300
 409.48531;20.91509; 96.78683
 410.60271;20.96885; 96.75050
 411.72011;21.02244; 96.71330
 412.83751;21.07586; 96.67664
 413.95491;21.12934; 96.63973
 415.07231;21.18302; 96.60220
 416.18971;21.23660; 96.56410
 417.30711;21.29022; 96.52541
 418.42451;21.34404; 96.48583
 419.54191;21.39771; 96.44533
 420.65931;21.45125; 96.40346
 421.77671;21.50485; 96.36181
 422.89411;21.55857; 96.31927
 424.01151;21.61226; 96.27594
 425.12891;21.66583; 96.23280
 426.24631;21.71948; 96.18771
 427.36371;21.77322; 96.14325
 428.48111;21.82700; 96.09657
 429.59851;21.88061; 96.04714
 430.71591;21.93411; 95.99841
 431.83331;21.98773; 95.94898
 432.95071;22.04143; 95.89816
 434.06811;22.09519; 95.84695
 435.18551;22.14876; 95.79532
 436.30291;22.20216; 95.74152
 437.42031;22.25572; 95.68553
 438.53771;22.30929; 95.62708
 439.65511;22.36270; 95.56997
 440.77251;22.41620; 95.51047
 441.88991;22.46970; 95.44971
 443.00731;22.52316; 95.38811
 444.12471;22.57650; 95.32397
 445.24211;22.63000; 95.25842
 446.35951;22.68351; 95.19129
 447.47691;22.73685; 95.12102
 448.59430;22.79029; 95.05076
 449.71170;22.84365; 94.97941
 450.82910;22.89699; 94.90652
 451.94650;22.95033; 94.83151
 453.06390;23.00366; 94.75442
 454.18130;23.05698; 94.67585
 455.29870;23.11052; 94.59567
 456.41610;23.16424; 94.50975
 457.53350;23.21807; 94.42520
 458.65090;23.27203; 94.33786
 459.76830;23.32594; 94.24839
 460.88570;23.37995; 94.15607
 462.00310;23.43419; 94.05964
 463.12050;23.48857; 93.86370
 464.23790;23.54298; 93.79685
 465.35530;23.59736; 93.71018
 466.47270;23.65172; 93.58135
 467.59010;23.70607; 93.44086
 468.70750;23.76072; 93.34553
 469.82490;23.81545; 93.16866
 470.94230;23.86998; 93.02992
 472.05970;23.92437; 92.88775
 473.17710;23.97866; 92.73735
 474.29450;24.03299; 92.58337
 475.41190;24.08721; 92.42385
 476.52930;24.14133; 92.26123
 477.64670;24.19536; 92.09835
 478.76410;24.24924; 91.92975
 479.88150;24.30301; 91.75755
 480.99890;24.35675; 91.58079
 482.11630;24.41048; 91.40462
 483.23370;24.46396; 91.22662
 484.35110;24.51738; 91.05404
 485.46850;24.57089; 90.88271
 486.58590;24.62432; 90.71413
 487.70330;24.67767; 90.54710
 488.82070;24.73090; 90.38257
 489.93810;24.78420; 90.21768
 491.05549;24.83765; 90.05478
 492.17289;24.89083; 89.88869
 493.29029;24.94360; 89.73200
 494.40769;24.99638; 89.57849
 495.52509;25.04932; 89.42678
 496.64249;25.10225; 89.27631
 497.75989;25.15518; 89.12733
 498.87729;25.20815; 88.98118
 499.99469;25.26101; 88.83808
 501.11209;25.31390; 88.69444
 502.22949;25.36693; 88.55518
 503.34689;25.42001; 88.41807
 504.46429;25.47316; 88.28254
 505.58169;25.52639; 88.15090
 506.69909;25.57960; 88.02202
 507.81649;25.63279; 87.89535
 508.93389;25.68600; 87.78168
 510.05129;25.73924; 87.68274
 511.16869;25.79258; 87.55107
 512.28609;25.84601; 87.41291
 513.40349;25.89953; 87.32726
 514.52089;25.95323; 87.19857
 515.63829;26.00687; 87.09497
 516.75569;26.06034; 86.98400
 517.87309;26.11399; 86.85318
 518.99049;26.16778; 86.77660
 520.10789;26.22142; 86.68417
 521.22529;26.27517; 86.56569
 522.34269;26.32909; 86.48638
 523.46009;26.38300; 86.39563
 524.57749;26.43685; 86.30461
 525.69489;26.49069; 86.21511
 526.81229;26.54470; 86.12794
 527.92969;26.59877; 86.04104
 529.04709;26.65282; 85.95973
 530.16449;26.70687; 85.87991
 531.28189;26.76104; 85.80330
 532.39929;26.81533; 85.72870
 533.51669;26.86970; 85.65619
 534.63408;26.92394; 85.58511
 535.75148;26.97801; 85.51425
 536.86888;27.03213; 85.44724
 537.98628;27.08637; 85.38167
 539.10368;27.14076; 85.31726
 540.22108;27.19524; 85.25576
 541.33848;27.24967; 85.19389
 542.45588;27.30410; 85.13392
 543.57328;27.35853; 85.07617
 544.69068;27.41306; 85.01788
 545.80808;27.46769; 84.96178
 546.92548;27.52234; 84.90711
 548.04288;27.57699; 84.85317
 549.16028;27.63170; 84.80016
 550.27768;27.68627; 84.74918
 551.39508;27.74081; 84.69811
 552.51248;27.79543; 84.64841
 553.62988;27.85011; 84.59839
 554.74728;27.90476; 84.55101
 555.86468;27.95955; 84.50369
 556.98208;28.01430; 84.45718
 558.09948;28.06893; 84.41158
 559.21688;28.12353; 84.36737
 560.33428;28.17812; 84.32313
 561.45168;28.23278; 84.28028
 562.56908;28.28748; 84.23583
 563.68648;28.34215; 84.19277
 564.80388;28.39676; 84.15111
 565.92128;28.45140; 84.10935
 567.03868;28.50600; 84.06830
 568.15608;28.56060; 84.02827
 569.27348;28.61519; 83.98790
 570.39088;28.66976; 83.94774
 571.50828;28.72441; 83.90740
 572.62568;28.77892; 83.86856
 573.74308;28.83327; 83.82976
 574.86048;28.88778; 83.79216
 575.97788;28.94224; 83.75528
 577.09528;28.99652; 83.71667
 578.21267;29.05098; 83.67911
 579.33007;29.10551; 83.64292
 580.44747;29.15999; 83.60563
 581.56487;29.21451; 83.56892
 582.68227;29.26887; 83.53288
 583.79967;29.32314; 83.49708
 584.91707;29.37757; 83.46126
 586.03447;29.43210; 83.42569
 587.15187;29.48663; 83.39090
 588.26927;29.54097; 83.35556
 589.38667;29.59520; 83.32109
 590.50407;29.64959; 83.28848
 591.62147;29.70422; 83.25539
 592.73887;29.75860; 83.22244
 593.85627;29.81275; 83.18927
 594.97367;29.86703; 83.15681
 596.09107;29.92133; 83.12399
 597.20847;29.97572; 83.08995
 598.32587;30.03014; 83.05764
 599.44327;30.08454; 83.02527
 600.56067;30.13898; 82.99346
 601.67807;30.19321; 82.96027
 602.79547;30.24727; 82.92890
 603.91287;30.30154; 82.89722
 605.03027;30.35590; 82.86558
 606.14767;30.41012; 82.83224
 607.26507;30.46436; 82.80168
 608.38247;30.51850; 82.77044
 609.49987;30.57274; 82.73847
 610.61727;30.62701; 82.70807
 611.73467;30.68126; 82.67700
 612.85207;30.73561; 82.64682
 613.96947;30.79007; 82.61657
 615.08687;30.84432; 82.58465
 616.20427;30.89837; 82.55495
 617.32167;30.95245; 82.52468
 618.43907;31.00666; 82.49506
 619.55647;31.06081; 82.46486
 620.67386;31.11491; 82.43499
 621.79126;31.16900; 82.40493
 622.90866;31.22318; 82.37659
 624.02606;31.27757; 82.34749
 625.14346;31.33186; 82.31930
 626.26086;31.38594; 82.29184
 627.37826;31.44003; 82.26350
 628.49566;31.49415; 82.23558
 629.61306;31.54824; 82.20753
 630.73046;31.60239; 82.17954
 631.84786;31.65656; 82.15217
 632.96526;31.71091; 82.12324
 634.08266;31.76530; 82.09497
 635.20006;31.81942; 82.06845
 636.31746;31.87347; 82.04205
 637.43486;31.92753; 82.01413
 638.55226;31.98160; 81.98691
 639.66966;32.03577; 81.96089
 640.78706;32.09002; 81.93364
 641.90446;32.14429; 81.90595
 643.02186;32.19854; 81.87972
 644.13926;32.25279; 81.85399
 645.25666;32.30698; 81.82769
 646.37406;32.36115; 81.80155
 647.49146;32.41549; 81.77563
 648.60886;32.46995; 81.75041
 649.72626;32.52437; 81.72361
 650.84366;32.57881; 81.69819
 651.96106;32.63310; 81.67371
 653.07846;32.68739; 81.64789
 654.19586;32.74170; 81.62300
 655.31326;32.79581; 81.59923
 656.43066;32.84989; 81.57434
 657.54806;32.90402; 81.54983
 658.66546;32.95821; 81.52430
 659.78286;33.01245; 81.50056
 660.90026;33.06676; 81.47574
 662.01766;33.12106; 81.45139
 663.13506;33.17546; 81.42795
 664.25245;33.22990; 81.40360
 665.36985;33.28416; 81.34576
 666.48725;33.33835; 81.31016
 667.60465;33.39275; 81.28439
 668.72205;33.44719; 81.26103
 669.83945;33.50147; 81.23724
 670.95685;33.55577; 81.21356
 672.07425;33.61017; 81.19057
 673.19165;33.66455; 81.16698
 674.30905;33.71885; 81.14398
 675.42645;33.77315; 81.12139
 676.54385;33.82750; 81.09746
 677.66125;33.88195; 81.07397
 678.77865;33.93632; 81.05254
 679.89605;33.99056; 81.03081
 681.01345;34.04488; 81.00863
 682.13085;34.09914; 80.98597
 683.24825;34.15345; 80.96312
 684.36565;34.20773; 80.94060
 685.48305;34.26200; 80.91915
 686.60045;34.31628; 80.89694
 687.71785;34.37057; 80.87482
 688.83525;34.42487; 80.85275
 689.95265;34.47916; 80.83026
 691.07005;34.53339; 80.80732
 692.18745;34.58774; 80.78495
 693.30485;34.64205; 80.76330
 694.42225;34.69629; 80.74103
 695.53965;34.75046; 80.71833
 696.65705;34.80461; 80.69563
 697.77445;34.85879; 80.67380
 698.89185;34.91307; 80.65265
 700.00925;34.96734; 80.63033
 701.12665;35.02168; 80.60804
 702.24405;35.07597; 80.58597
 703.36145;35.13020; 80.56462
 704.47885;35.18454; 80.54369
 705.59625;35.23892; 80.52235
 706.71365;35.29339; 80.49893
 707.83104;35.34772; 80.47653
 708.94844;35.40185; 80.45565
 710.06584;35.45607; 80.43370
 711.18324;35.51043; 80.41143
 712.30064;35.56471; 80.38990
 713.41804;35.61907; 80.36858
 714.53544;35.67355; 80.34747
 715.65284;35.72797; 80.32433
 716.77024;35.78233; 80.30245
 717.88764;35.83674; 80.28108
 719.00504;35.89103; 80.25940
 720.12244;35.94536; 80.23773
 721.23984;35.99971; 80.21505
 722.35724;36.05400; 80.19285
 723.47464;36.10835; 80.17104
 724.59204;36.16269; 80.14952
 725.70944;36.21702; 80.12814
 726.82684;36.27146; 80.10620
 727.94424;36.32585; 80.08419
 729.06164;36.38021; 80.06196
 730.17904;36.43448; 80.04103
 731.29644;36.48875; 80.02006
 732.41384;36.54315; 79.99817
 733.53124;36.59764; 79.97694
 734.64864;36.65202; 79.95580
 735.76604;36.70636; 79.93489
 736.88344;36.76090; 79.91334
 738.00084;36.81544; 79.89121
 739.11824;36.86991; 79.87006
 740.23564;36.92453; 79.84877
 741.35304;36.97905; 79.82730
 742.47044;37.03350; 79.80604
 743.58784;37.08800; 79.78547
 744.70524;37.14247; 79.76452
 745.82264;37.19702; 79.74297
 746.94004;37.25165; 79.72178
 748.05744;37.30610; 79.70090
 749.17484;37.36059; 79.68016
 750.29224;37.41517; 79.66016
 751.40963;37.46972; 79.63885
 752.52703;37.52428; 79.61885
 753.64443;37.57889; 79.59917
 754.76183;37.63352; 79.57946
 755.87923;37.68814; 79.55825
 756.99663;37.74271; 79.53864
 758.11403;37.79738; 79.51848
 759.23143;37.85210; 79.50021
 760.34883;37.90671; 79.48092
 761.46623;37.96136; 79.46185
 762.58363;38.01612; 79.44212
 763.70103;38.07084; 79.42168
 764.81843;38.12547; 79.40236
 765.93583;38.18006; 79.38320
 767.05323;38.23472; 79.36437
 768.17063;38.28949; 79.34559
 769.28803;38.34409; 79.32880
 770.40543;38.39873; 79.31196
 771.52283;38.45343; 79.29344
 772.64023;38.50821; 79.27394
 773.75763;38.56300; 79.25571
 774.87503;38.61773; 79.23857
 775.99243;38.67254; 79.22084
 777.10983;38.72743; 79.20262
 778.22723;38.78227; 79.18491
 779.34463;38.83718; 79.16811
 780.46203;38.89210; 79.15019
 781.57943;38.94685; 79.13237
 782.69683;39.00171; 79.11729
 783.81423;39.05662; 79.10346
 784.93163;39.11143; 79.08805
 786.04903;39.16625; 79.07192
 787.16643;39.22119; 79.05623
 788.28383;39.27636; 79.03941
 789.40123;39.33167; 79.02412
 790.51863;39.38695; 79.00937
 791.63603;39.44220; 78.99435
 792.75343;39.49723; 78.97905
 793.87082;39.55229; 78.96463
 794.98822;39.60751; 78.94862
 796.10562;39.66269; 78.93331
 797.22302;39.71780; 78.91937
 798.34042;39.77285; 78.90498
 799.45782;39.82781; 78.89159
 800.57522;39.88283; 78.87739
 801.69262;39.93788; 78.86333
 802.81002;39.99284; 78.85035
 803.92742;40.04783; 78.83899
 805.04482;40.10295; 78.82765
 806.16222;40.15816; 78.81515
 807.27962;40.21326; 78.79875
 808.39702;40.26839; 78.78318
 809.51442;40.32337; 78.77027
 810.63182;40.37847; 78.75833
 811.74922;40.43361; 78.74749
 812.86662;40.48851; 78.73710
 813.98402;40.54353; 78.72564
 815.10142;40.59882; 78.71176
 816.21882;40.65401; 78.69855
 817.33622;40.70910; 78.68671
 818.45362;40.76434; 78.67596
 819.57102;40.81957; 78.66649
 820.68842;40.87480; 78.65647
 821.80582;40.93012; 78.64629
 822.92322;40.98539; 78.63493
 824.04062;41.04048; 78.62330
 825.15802;41.09549; 78.61167
 826.27542;41.15058; 78.60067
 827.39282;41.20582; 78.59039
 828.51022;41.26097; 78.57998
 829.62762;41.31595; 78.57056
 830.74502;41.37103; 78.56103
 831.86242;41.42619; 78.55142
 832.97982;41.48143; 78.54089
 834.09722;41.53654; 78.53083
 835.21462;41.59171; 78.52117
 836.33202;41.64685; 78.51120
 837.44941;41.70187; 78.50137
 838.56681;41.75691; 78.49141
 839.68421;41.81215; 78.48173
 840.80161;41.86727; 78.47199
 841.91901;41.92237; 78.46263
 843.03641;41.97757; 78.45345
 844.15381;42.03264; 78.44431
 845.27121;42.08774; 78.43511
 846.38861;42.14294; 78.42692
 847.50601;42.19807; 78.41761
 848.62341;42.25326; 78.40904
 849.74081;42.30850; 78.39995
 850.85821;42.36371; 78.39101
 851.97561;42.41881; 78.38266
 853.09301;42.47400; 78.37297
 854.21041;42.52930; 78.36371
 855.32781;42.58458; 78.35584
 856.44521;42.63999; 78.34752
 857.56261;42.69561; 78.33920
 858.68001;42.75130; 78.33093
 859.79741;42.80694; 78.32279
 860.91481;42.86257; 78.31472
 862.03221;42.91820; 78.30673
 863.14961;42.97378; 78.29870
 864.26701;43.02943; 78.29043
 865.38441;43.08510; 78.28333
 866.50181;43.14059; 78.27473
 867.61921;43.19619; 78.26637
 868.73661;43.25196; 78.25933
 869.85401;43.30747; 78.25263
 870.97141;43.36299; 78.24653
 872.08881;43.41841; 78.23998
 873.20621;43.47374; 78.23316
 874.32361;43.52912; 78.22595
 875.44101;43.58458; 78.21835
 876.55841;43.63995; 78.21094
 877.67581;43.69526; 78.20377
 878.79321;43.75067; 78.19784
 879.91061;43.80599; 78.19097
 881.02800;43.86132; 78.18475
 882.14540;43.91681; 78.17786
 883.26280;43.97218; 78.17035
 884.38020;44.02748; 78.16355
 885.49760;44.08301; 78.15630
 886.61500;44.13853; 78.14930
 887.73240;44.19390; 78.14271
 888.84980;44.24931; 78.13630
 889.96720;44.30467; 78.13029
 891.08460;44.36004; 78.12315
 892.20200;44.41548; 78.11620
 893.31940;44.47089; 78.11056
 894.43680;44.52646; 78.10417
 895.55420;44.58189; 78.09851
 896.67160;44.63716; 78.09310
 897.78900;44.69247; 78.08707
 898.90640;44.74790; 78.08084
 900.02380;44.80328; 78.07472
 901.14120;44.85869; 78.06809
 902.25860;44.91416; 78.06171
 903.37600;44.96970; 78.05487
 904.49340;45.02518; 78.04847
 905.61080;45.08049; 78.04287
 906.72820;45.13583; 78.03619
 907.84560;45.19118; 78.02862
 908.96300;45.24647; 78.02237
 910.08040;45.30178; 78.01632
 911.19780;45.35716; 78.01039
 912.31520;45.41258; 78.00480
 913.43260;45.46793; 77.99976
 914.55000;45.52324; 77.99444
 915.66740;45.57860; 77.98944
 916.78480;45.63386; 77.98412
 917.90220;45.68913; 77.97873
 919.01960;45.74460; 77.97237
 920.13700;45.79994; 77.96539
 921.25440;45.85528; 77.95899
 922.37180;45.91062; 77.95315
 923.48919;45.96588; 77.94756
 924.60659;46.02110; 77.94236
 925.72399;46.07639; 77.93701
 926.84139;46.13181; 77.93139
 927.95879;46.18720; 77.92570
 929.07619;46.24257; 77.91890
 930.19359;46.29791; 77.91340
 931.31099;46.35327; 77.90717
 932.42839;46.40868; 77.90130
 933.54579;46.46410; 77.89459
 934.66319;46.51945; 77.88965
 935.78059;46.57473; 77.88388
 936.89799;46.63006; 77.87851
 938.01539;46.68540; 77.87250
 939.13279;46.74096; 77.86782
 940.25019;46.79638; 77.86191
 941.36759;46.85171; 77.85650
 942.48499;46.90707; 77.85144
 943.60239;46.96235; 77.84569
 944.71979;47.01774; 77.83942
 945.83719;47.07319; 77.83379
 946.95459;47.12854; 77.82830
 948.07199;47.18400; 77.82204
 949.18939;47.23953; 77.81700
 950.30679;47.29506; 77.81048
 951.42419;47.35047; 77.80532
 952.54159;47.40582; 77.79872
 953.65899;47.46138; 77.79370
 954.77639;47.51690; 77.78848
 955.89379;47.57235; 77.78306
 957.01119;47.62793; 77.77824
 958.12859;47.68360; 77.77381
 959.24599;47.73919; 77.76818
 960.36339;47.79478; 77.76224
 961.48079;47.85045; 77.75787
 962.59819;47.90611; 77.75189
 963.71559;47.96187; 77.74616
 964.83299;48.01755; 77.74026
 965.95039;48.07331; 77.73531
 967.06778;48.12899; 77.73009
 968.18518;48.18466; 77.72527
 969.30258;48.24040; 77.72187
 970.41998;48.29610; 77.71619
 971.53738;48.35193; 77.70995
 972.65478;48.40781; 77.70385
 973.77218;48.46369; 77.69923
 974.88958;48.51957; 77.69378
 976.00698;48.57535; 77.68770
 977.12438;48.63115; 77.68242
 978.24178;48.68704; 77.67767
 979.35918;48.74287; 77.67183
 980.47658;48.79870; 77.66581
 981.59398;48.85452; 77.65950
 982.71138;48.91045; 77.65433
 983.82878;48.96629; 77.64926
 984.94618;49.02226; 77.64520
 986.06358;49.07829; 77.64068
 987.18098;49.13422; 77.63527
 988.29838;49.19025; 77.63007
 989.41578;49.24635; 77.62505
 990.53318;49.30253; 77.62055
 991.65058;49.35862; 77.61483
 992.76798;49.41465; 77.60931
 993.88538;49.47086; 77.60451
 995.00278;49.52705; 77.59832
 996.12018;49.58320; 77.59283
 997.23758;49.63933; 77.58770
 998.35498;49.69542; 77.58256
 999.47238;49.75149; 77.57717
1000.58978;49.80765; 77.57114
1001.70718;49.86377; 77.56529
1002.82458;49.91980; 77.55983
1003.94198;49.97581; 77.55421
1005.05938;50.03195; 77.54875
1006.17678;50.08818; 77.54387
1007.29418;50.14433; 77.53834
1008.41158;50.20043; 77.53322
1009.52898;50.25656; 77.52712
1010.64637;50.31269; 77.52215
1011.76377;50.36877; 77.51726
1012.88117;50.42482; 77.51200
1013.99857;50.48096; 77.50803
1015.11597;50.53710; 77.50292
1016.23337;50.59319; 77.49798
1017.35077;50.64935; 77.49275
1018.46817;50.70538; 77.48763
1019.58557;50.76126; 77.48214
1020.70297;50.81723; 77.47665
1021.82037;50.87329; 77.47142
1022.93777;50.92931; 77.46595
1024.05517;50.98544; 77.46080
1025.17257;51.04149; 77.45509
1026.28997;51.09755; 77.44896
1027.40737;51.15362; 77.44411
1028.52477;51.20963; 77.43909
1029.64217;51.26574; 77.43315
1030.75957;51.32184; 77.42806
1031.87697;51.37793; 77.42242
1032.99437;51.43408; 77.41756
1034.11177;51.49010; 77.41152
1035.22917;51.54616; 77.40593
1036.34657;51.60227; 77.40104
1037.46397;51.65837; 77.39593
1038.58137;51.71437; 77.39068
1039.69877;51.77040; 77.38499
1040.81617;51.82648; 77.37929
1041.93357;51.88253; 77.37432
1043.05097;51.93869; 77.36869
1044.16837;51.99490; 77.36327
1045.28577;52.05095; 77.35724
1046.40317;52.10694; 77.35252
1047.52057;52.16295; 77.34772
1048.63797;52.21899; 77.34366
1049.75537;52.27502; 77.33830
1050.87277;52.33109; 77.33280
1051.99017;52.38722; 77.32848
1053.10756;52.44336; 77.32335
1054.22496;52.49936; 77.31809
1055.34236;52.55533; 77.31248
1056.45976;52.61145; 77.30725
1057.57716;52.66768; 77.30092
1058.69456;52.72379; 77.29528
1059.81196;52.77986; 77.28968
1060.92936;52.83601; 77.28521
1062.04676;52.89228; 77.27922
1063.16416;52.94843; 77.27422
1064.28156;53.00458; 77.26693
1065.39896;53.06081; 77.26024
1066.51636;53.11699; 77.25368
1067.63376;53.17326; 77.24773
1068.75116;53.22958; 77.24232
1069.86856;53.28591; 77.23764
1070.98596;53.34232; 77.23278
1072.10336;53.39870; 77.22729
1073.22076;53.45518; 77.22222
1074.33816;53.51170; 77.21702
1075.45556;53.56820; 77.21157
1076.57296;53.62469; 77.20531
1077.69036;53.68116; 77.19922
1078.80776;53.73783; 77.19289
1079.92516;53.79459; 77.18730
1081.04256;53.85130; 77.18144
1082.15996;53.90800; 77.17548
1083.27736;53.96478; 77.16933
1084.39476;54.02166; 77.16253
1085.51216;54.07852; 77.15889
1086.62956;54.13536; 77.15395
1087.74696;54.19234; 77.14845
1088.86436;54.24939; 77.14308
1089.98176;54.30634; 77.13807
1091.09916;54.36330; 77.13216
1092.21656;54.42038; 77.12592
1093.33396;54.47751; 77.12018
1094.45136;54.53459; 77.11450
1095.56876;54.59185; 77.10851
1096.68615;54.64916; 77.10246
1097.80355;54.70641; 77.09649
1098.92095;54.76370; 77.09106
1100.03835;54.82098; 77.08632
1101.15575;54.87834; 77.08079
1102.27315;54.93576; 77.07430
1103.39055;54.99310; 77.06835
1104.50795;55.05055; 77.06252
1105.62535;55.10799; 77.05747
1106.74275;55.16539; 77.05194
1107.86015;55.22297; 77.04692
1108.97755;55.28062; 77.04166
1110.09495;55.33835; 77.03620
1111.21235;55.39600; 77.03030
1112.32975;55.45360; 77.02550
1113.44715;55.51115; 77.01905
1114.56455;55.56881; 77.01240
1115.68195;55.62660; 77.00611
1116.79935;55.68433; 76.99866
1117.91675;55.74206; 76.99276
1119.03415;55.79987; 76.98650
1120.15155;55.85768; 76.98050
1121.26895;55.91555; 76.97542
1122.38635;55.97342; 76.96896
1123.50375;56.03133; 76.96350
1124.62115;56.08926; 76.95749
1125.73855;56.14712; 76.95212
1126.85595;56.20496; 76.94644
1127.97335;56.26296; 76.94154
1129.09075;56.32093; 76.93593
1130.20815;56.37887; 76.92972
1131.32555;56.43686; 76.92342
1132.44295;56.49487; 76.91779
1133.56035;56.55301; 76.91153
1134.67775;56.61096; 76.90419
1135.79515;56.66892; 76.89834
1136.91255;56.72699; 76.89201
1138.02995;56.78501; 76.88633
1139.14735;56.84299; 76.88030
1140.26474;56.90097; 76.87443
1141.38214;56.95894; 76.86868
1142.49954;57.01688; 76.86313
1143.61694;57.07481; 76.85784
1144.73434;57.13272; 76.85163
1145.85174;57.19061; 76.84569
1146.96914;57.24859; 76.83973
1148.08654;57.30649; 76.83364
1149.20394;57.36432; 76.82740
1150.32134;57.42224; 76.82182
1151.43874;57.48002; 76.81566
1152.55614;57.53767; 76.80967
1153.67354;57.59536; 76.80389
1154.79094;57.65310; 76.79780
1155.90834;57.71088; 76.79220